<?xml version="1.0" ?>
<!-- =================================================================================== -->
<!-- |    This document was autogenerated by xacro from /home/ydg/mani_ws/src/mani/urdf/6dof_mani.xacro | -->
<!-- |    EDITING THIS FILE BY HAND IS NOT RECOMMENDED                                 | -->
<!-- =================================================================================== -->
<robot name="6dof_mani">
  <material name="silver">
    <color rgba="0.700 0.700 0.700 1.000"/>
  </material>
  <material name="white">
    <color rgba="1.00 1.00 1.00 1.000"/>
  </material>
  <gazebo>
    <plugin filename="libgazebo_ros2_control.so" name="gazebo_ros2_control">
      <robotNamespace>/</robotNamespace>
      <parameters>/home/ydg/mani_ws/src/mani/config/ros2_controllers.yaml</parameters>
    </plugin>
  </gazebo>
  <gazebo reference="base_link">
    <material>Gazebo/Silver</material>
    <mu1>0.2</mu1>
    <mu2>0.2</mu2>
    <self_collide>true</self_collide>
    <gravity>0</gravity>
  </gazebo>
  <gazebo reference="link_8_1">
    <material>Gazebo/Silver</material>
    <mu1>0.2</mu1>
    <mu2>0.2</mu2>
    <self_collide>true</self_collide>
  </gazebo>
  <gazebo reference="link_9_1">
    <material>Gazebo/Silver</material>
    <mu1>0.2</mu1>
    <mu2>0.2</mu2>
    <self_collide>true</self_collide>
  </gazebo>
  <gazebo reference="link_7_1">
    <material>Gazebo/Silver</material>
    <mu1>0.2</mu1>
    <mu2>0.2</mu2>
    <self_collide>true</self_collide>
  </gazebo>
  <gazebo reference="link_6_1">
    <material>Gazebo/Silver</material>
    <mu1>0.2</mu1>
    <mu2>0.2</mu2>
    <self_collide>true</self_collide>
  </gazebo>
  <gazebo reference="link_5_1">
    <material>Gazebo/Silver</material>
    <mu1>0.2</mu1>
    <mu2>0.2</mu2>
    <self_collide>true</self_collide>
  </gazebo>
  <gazebo reference="link_4_1">
    <material>Gazebo/Silver</material>
    <mu1>0.2</mu1>
    <mu2>0.2</mu2>
    <self_collide>true</self_collide>
  </gazebo>
  <gazebo reference="link_3_1">
    <material>Gazebo/Silver</material>
    <mu1>0.2</mu1>
    <mu2>0.2</mu2>
    <self_collide>true</self_collide>
  </gazebo>
  <gazebo reference="link_2_1">
    <material>Gazebo/Silver</material>
    <mu1>0.2</mu1>
    <mu2>0.2</mu2>
    <self_collide>true</self_collide>
  </gazebo>
  <gazebo reference="link_1_1">
    <material>Gazebo/Silver</material>
    <mu1>0.2</mu1>
    <mu2>0.2</mu2>
    <self_collide>true</self_collide>
  </gazebo>
  <transmission name="Slider_1_tran">
    <type>transmission_interface/SimpleTransmission</type>
    <joint name="Slider_1">
      <hardwareInterface>Position</hardwareInterface>
    </joint>
    <actuator name="Slider_1_actr">
      <hardwareInterface>Position</hardwareInterface>
      <mechanicalReduction>1</mechanicalReduction>
    </actuator>
  </transmission>
  <transmission name="Slider_2_tran">
    <type>transmission_interface/SimpleTransmission</type>
    <joint name="Slider_2">
      <hardwareInterface>Position</hardwareInterface>
    </joint>
    <actuator name="Slider_2_actr">
      <hardwareInterface>Position</hardwareInterface>
      <mechanicalReduction>1</mechanicalReduction>
    </actuator>
  </transmission>
  <transmission name="Revolute_1_tran">
    <type>transmission_interface/SimpleTransmission</type>
    <joint name="Revolute_1">
      <hardwareInterface>Position</hardwareInterface>
    </joint>
    <actuator name="Revolute_1_actr">
      <hardwareInterface>Position</hardwareInterface>
      <mechanicalReduction>1</mechanicalReduction>
    </actuator>
  </transmission>
  <transmission name="Revolute_2_tran">
    <type>transmission_interface/SimpleTransmission</type>
    <joint name="Revolute_2">
      <hardwareInterface>Position</hardwareInterface>
    </joint>
    <actuator name="Revolute_2_actr">
      <hardwareInterface>Position</hardwareInterface>
      <mechanicalReduction>1</mechanicalReduction>
    </actuator>
  </transmission>
  <transmission name="Revolute_3_tran">
    <type>transmission_interface/SimpleTransmission</type>
    <joint name="Revolute_3">
      <hardwareInterface>Position</hardwareInterface>
    </joint>
    <actuator name="Revolute_3_actr">
      <hardwareInterface>Position</hardwareInterface>
      <mechanicalReduction>1</mechanicalReduction>
    </actuator>
  </transmission>
  <transmission name="Revolute_4_tran">
    <type>transmission_interface/SimpleTransmission</type>
    <joint name="Revolute_4">
      <hardwareInterface>Position</hardwareInterface>
    </joint>
    <actuator name="Revolute_4_actr">
      <hardwareInterface>Position</hardwareInterface>
      <mechanicalReduction>1</mechanicalReduction>
    </actuator>
  </transmission>
  <transmission name="Revolute_5_tran">
    <type>transmission_interface/SimpleTransmission</type>
    <joint name="Revolute_5">
      <hardwareInterface>Position</hardwareInterface>
    </joint>
    <actuator name="Revolute_5_actr">
      <hardwareInterface>Position</hardwareInterface>
      <mechanicalReduction>1</mechanicalReduction>
    </actuator>
  </transmission>
  <transmission name="Revolute_6_tran">
    <type>transmission_interface/SimpleTransmission</type>
    <joint name="Revolute_6">
      <hardwareInterface>Position</hardwareInterface>
    </joint>
    <actuator name="Revolute_6_actr">
      <hardwareInterface>Position</hardwareInterface>
      <mechanicalReduction>1</mechanicalReduction>
    </actuator>
  </transmission>
  <link name="world"/>
  <link name="base_link">
    <inertial>
      <origin rpy="0 0 0" xyz="2.149744881531404e-17 2.149744881531404e-17 0.22234748143971175"/>
      <mass value="53.13771672353255"/>
      <inertia ixx="1.926507" ixy="0.0" ixz="0.0" iyy="1.926507" iyz="0.0" izz="0.142694"/>
    </inertial>
    <visual>
      <origin rpy="0 0 0" xyz="0 0 0"/>
      <geometry>
        <mesh filename="file:///home/ydg/mani_ws/install/mani/share/mani/meshes/base_link.stl" scale="0.001 0.001 0.001"/>
      </geometry>
      <material name="silver"/>
    </visual>
    <collision>
      <origin rpy="0 0 0" xyz="0 0 0"/>
      <geometry>
        <mesh filename="file:///home/ydg/mani_ws/install/mani/share/mani/meshes/base_link.stl" scale="0.001 0.001 0.001"/>
      </geometry>
    </collision>
  </link>
  <joint name="fixed_joint" type="fixed">
    <parent link="world"/>
    <child link="base_link"/>
    <origin rpy="0 0 -1.570796" xyz="0 0 0"/>
  </joint>
  <link name="link_8_1">
    <inertial>
      <origin rpy="0 0 0" xyz="-0.039340998690695 7.58658880162244e-09 -0.05486038510225294"/>
      <mass value="0.10049075548979451"/>
      <inertia ixx="2.8e-05" ixy="0.0" ixz="0.0" iyy="1.6e-05" iyz="-0.0" izz="1.3e-05"/>
    </inertial>
    <visual>
      <origin rpy="0 0 0" xyz="-0.0 -0.5 -0.2"/>
      <geometry>
        <mesh filename="file:///home/ydg/mani_ws/install/mani/share/mani/meshes/link_8_1.stl" scale="0.001 0.001 0.001"/>
      </geometry>
      <material name="silver"/>
    </visual>
    <collision>
      <origin rpy="0 0 0" xyz="-0.0 -0.5 -0.2"/>
      <geometry>
        <mesh filename="file:///home/ydg/mani_ws/install/mani/share/mani/meshes/link_8_1.stl" scale="0.001 0.001 0.001"/>
      </geometry>
    </collision>
  </link>
  <link name="link_9_1">
    <inertial>
      <origin rpy="0 0 0" xyz="0.039340998774234935 -6.868324020636862e-09 -0.054860385776580256"/>
      <mass value="0.1004907509297747"/>
      <inertia ixx="2.8e-05" ixy="0.0" ixz="-0.0" iyy="1.6e-05" iyz="-0.0" izz="1.3e-05"/>
    </inertial>
    <visual>
      <origin rpy="0 0 0" xyz="-0.0 -0.5 -0.2"/>
      <geometry>
        <mesh filename="file:///home/ydg/mani_ws/install/mani/share/mani/meshes/link_9_1.stl" scale="0.001 0.001 0.001"/>
      </geometry>
      <material name="silver"/>
    </visual>
    <collision>
      <origin rpy="0 0 0" xyz="-0.0 -0.5 -0.2"/>
      <geometry>
        <mesh filename="file:///home/ydg/mani_ws/install/mani/share/mani/meshes/link_9_1.stl" scale="0.001 0.001 0.001"/>
      </geometry>
    </collision>
  </link>
  <link name="link_7_1">
    <inertial>
      <origin rpy="0 0 0" xyz="0.0 1.1102230246251565e-16 -0.00490145769266237"/>
      <mass value="0.5482219872439408"/>
      <inertia ixx="0.000212" ixy="0.0" ixz="0.0" iyy="0.000554" iyz="0.0" izz="0.000758"/>
    </inertial>
    <visual>
      <origin rpy="0 0 0" xyz="-0.0 -0.5 -0.17"/>
      <geometry>
        <mesh filename="file:///home/ydg/mani_ws/install/mani/share/mani/meshes/link_7_1.stl" scale="0.001 0.001 0.001"/>
      </geometry>
      <material name="silver"/>
    </visual>
    <collision>
      <origin rpy="0 0 0" xyz="-0.0 -0.5 -0.17"/>
      <geometry>
        <mesh filename="file:///home/ydg/mani_ws/install/mani/share/mani/meshes/link_7_1.stl" scale="0.001 0.001 0.001"/>
      </geometry>
    </collision>
  </link>
  <link name="link_6_1">
    <inertial>
      <origin rpy="0 0 0" xyz="-0.02999999968436338 -5.551115123125783e-17 -0.0006655542658631219"/>
      <mass value="3.7517142442249574"/>
      <inertia ixx="0.004765" ixy="0.0" ixz="0.0" iyy="0.003547" iyz="0.0" izz="0.003453"/>
    </inertial>
    <visual>
      <origin rpy="0 0 0" xyz="-0.03 -0.5 -0.22"/>
      <geometry>
        <mesh filename="file:///home/ydg/mani_ws/install/mani/share/mani/meshes/link_6_1.stl" scale="0.001 0.001 0.001"/>
      </geometry>
      <material name="silver"/>
    </visual>
    <collision>
      <origin rpy="0 0 0" xyz="-0.03 -0.5 -0.22"/>
      <geometry>
        <mesh filename="file:///home/ydg/mani_ws/install/mani/share/mani/meshes/link_6_1.stl" scale="0.001 0.001 0.001"/>
      </geometry>
    </collision>
  </link>
  <link name="link_5_1">
    <inertial>
      <origin rpy="0 0 0" xyz="-3.3978200457262537e-17 -5.551115123125783e-17 -0.04995217971199711"/>
      <mass value="8.404839941888653"/>
      <inertia ixx="0.018892" ixy="-0.0" ixz="-0.0" iyy="0.027299" iyz="-0.0" izz="0.023197"/>
    </inertial>
    <visual>
      <origin rpy="0 0 0" xyz="-0.0 -0.5 -0.3"/>
      <geometry>
        <mesh filename="file:///home/ydg/mani_ws/install/mani/share/mani/meshes/link_5_1.stl" scale="0.001 0.001 0.001"/>
      </geometry>
      <material name="silver"/>
    </visual>
    <collision>
      <origin rpy="0 0 0" xyz="-0.0 -0.5 -0.3"/>
      <geometry>
        <mesh filename="file:///home/ydg/mani_ws/install/mani/share/mani/meshes/link_5_1.stl" scale="0.001 0.001 0.001"/>
      </geometry>
    </collision>
  </link>
  <link name="link_4_1">
    <inertial>
      <origin rpy="0 0 0" xyz="-0.005393886723982707 -1.9101969062074176e-08 -0.0812452511717251"/>
      <mass value="57.15166854451474"/>
      <inertia ixx="1.131774" ixy="-0.0" ixz="0.025045" iyy="1.136453" iyz="-0.0" izz="0.228916"/>
    </inertial>
    <visual>
      <origin rpy="0 0 0" xyz="-0.0 -0.5 -0.7"/>
      <geometry>
        <mesh filename="file:///home/ydg/mani_ws/install/mani/share/mani/meshes/link_4_1.stl" scale="0.001 0.001 0.001"/>
      </geometry>
      <material name="silver"/>
    </visual>
    <collision>
      <origin rpy="0 0 0" xyz="-0.0 -0.5 -0.7"/>
      <geometry>
        <mesh filename="file:///home/ydg/mani_ws/install/mani/share/mani/meshes/link_4_1.stl" scale="0.001 0.001 0.001"/>
      </geometry>
    </collision>
  </link>
  <link name="link_3_1">
    <inertial>
      <origin rpy="0 0 0" xyz="-0.02063337713705643 0.006447937492402134 1.6172253536339554e-08"/>
      <mass value="44.82089050461812"/>
      <inertia ixx="0.191876" ixy="-0.005963" ixz="-0.0" iyy="0.352786" iyz="0.0" izz="0.335839"/>
    </inertial>
    <visual>
      <origin rpy="0 0 0" xyz="-0.2 -0.5 -0.7"/>
      <geometry>
        <mesh filename="file:///home/ydg/mani_ws/install/mani/share/mani/meshes/link_3_1.stl" scale="0.001 0.001 0.001"/>
      </geometry>
      <material name="silver"/>
    </visual>
    <collision>
      <origin rpy="0 0 0" xyz="-0.2 -0.5 -0.7"/>
      <geometry>
        <mesh filename="file:///home/ydg/mani_ws/install/mani/share/mani/meshes/link_3_1.stl" scale="0.001 0.001 0.001"/>
      </geometry>
    </collision>
  </link>
  <link name="link_2_1">
    <inertial>
      <origin rpy="0 0 0" xyz="0.004868630594462409 0.11715205013596279 1.8184465711001963e-08"/>
      <mass value="63.31704419351884"/>
      <inertia ixx="1.897499" ixy="0.036114" ixz="0.0" iyy="0.236785" iyz="-0.0" izz="1.902339"/>
    </inertial>
    <visual>
      <origin rpy="0 0 0" xyz="-0.2 0.0 -0.7"/>
      <geometry>
        <mesh filename="file:///home/ydg/mani_ws/install/mani/share/mani/meshes/link_2_1.stl" scale="0.001 0.001 0.001"/>
      </geometry>
      <material name="silver"/>
    </visual>
    <collision>
      <origin rpy="0 0 0" xyz="-0.2 0.0 -0.7"/>
      <geometry>
        <mesh filename="file:///home/ydg/mani_ws/install/mani/share/mani/meshes/link_2_1.stl" scale="0.001 0.001 0.001"/>
      </geometry>
    </collision>
  </link>
  <link name="link_1_1">
    <inertial>
      <origin rpy="0 0 0" xyz="0.01851625139495706 -1.3314793762482336e-08 0.09999999999999987"/>
      <mass value="50.98628790042472"/>
      <inertia ixx="0.23957" ixy="0.0" ixz="-0.0" iyy="0.363708" iyz="-0.0" izz="0.340669"/>
    </inertial>
    <visual>
      <origin rpy="0 0 0" xyz="-0.0 -0.0 -0.6"/>
      <geometry>
        <mesh filename="file:///home/ydg/mani_ws/install/mani/share/mani/meshes/link_1_1.stl" scale="0.001 0.001 0.001"/>
      </geometry>
      <material name="silver"/>
    </visual>
    <collision>
      <origin rpy="0 0 0" xyz="-0.0 -0.0 -0.6"/>
      <geometry>
        <mesh filename="file:///home/ydg/mani_ws/install/mani/share/mani/meshes/link_1_1.stl" scale="0.001 0.001 0.001"/>
      </geometry>
    </collision>
  </link>
  <joint name="Slider_1" type="prismatic">
    <origin rpy="0 0 0" xyz="0.0 0.0 0.03"/>
    <parent link="link_7_1"/>
    <child link="link_8_1"/>
    <axis xyz="1.0 0.0 0.0"/>
    <limit effort="100" lower="0.0" upper="0.0" velocity="100"/>
    <!--<limit upper="0.025" lower="0.0" effort="100" velocity="100"/>-->
  </joint>
  <joint name="Slider_2" type="prismatic">
    <origin rpy="0 0 0" xyz="0.0 0.0 0.03"/>
    <parent link="link_7_1"/>
    <child link="link_9_1"/>
    <axis xyz="1.0 0.0 0.0"/>
    <limit effort="100" lower="0.0" upper="0.0" velocity="100"/>
    <!--<limit upper="0.0" lower="-0.025" effort="100" velocity="100"/>-->
  </joint>
  <joint name="Revolute_6" type="revolute">
    <origin rpy="0 0 0" xyz="-0.03 0.0 -0.05"/>
    <parent link="link_6_1"/>
    <child link="link_7_1"/>
    <axis xyz="0.0 0.0 -1.0"/>
    <limit effort="100" lower="-3.141593" upper="3.141593" velocity="100"/>
  </joint>
  <joint name="Revolute_5" type="revolute">
    <origin rpy="0 0 0" xyz="0.03 0.0 -0.08"/>
    <parent link="link_5_1"/>
    <child link="link_6_1"/>
    <axis xyz="-1.0 0.0 0.0"/>
    <limit effort="100" lower="-1.570796" upper="1.570796" velocity="100"/>
  </joint>
  <joint name="Revolute_4" type="revolute">
    <origin rpy="0 0 0" xyz="0.0 0.0 -0.4"/>
    <parent link="link_4_1"/>
    <child link="link_5_1"/>
    <axis xyz="0.0 0.0 -1.0"/>
    <limit effort="100" lower="-3.141593" upper="3.141593" velocity="100"/>
  </joint>
  <joint name="Revolute_3" type="revolute">
    <origin rpy="0 0 0" xyz="-0.2 0.0 0.0"/>
    <parent link="link_3_1"/>
    <child link="link_4_1"/>
    <axis xyz="-1.0 0.0 0.0"/>
    <limit effort="100" lower="-4.712389" upper="1.570796" velocity="100"/>
  </joint>
  <joint name="Rigid_7" type="fixed">
    <origin rpy="0 0 0" xyz="0.0 0.5 0.0"/>
    <parent link="link_2_1"/>
    <child link="link_3_1"/>
  </joint>
  <joint name="Revolute_2" type="revolute">
    <origin rpy="0 0 0" xyz="0.2 -0.0 0.1"/>
    <parent link="link_1_1"/>
    <child link="link_2_1"/>
    <axis xyz="1.0 0.0 0.0"/>
    <limit effort="100" lower="-3.141593" upper="3.141593" velocity="100"/>
  </joint>
  <joint name="Revolute_1" type="revolute">
    <origin rpy="0 0 0" xyz="0.0 0.0 0.6"/>
    <parent link="base_link"/>
    <child link="link_1_1"/>
    <axis xyz="0.0 0.0 1.0"/>
    <limit effort="100" lower="-3.141593" upper="3.141593" velocity="100"/>
  </joint>
  <ros2_control name="mani_ros2_control" type="system">
    <hardware>
      <plugin>gazebo_ros2_control/GazeboSystem</plugin>
    </hardware>
    <joint name="Revolute_1">
      <command_interface name="position"/>
      <state_interface name="position"/>
      <state_interface name="velocity"/>
      <initial_position>0.0</initial_position>
    </joint>
    <joint name="Revolute_2">
      <command_interface name="position"/>
      <state_interface name="position"/>
      <state_interface name="velocity"/>
      <initial_position>0.0</initial_position>
    </joint>
    <joint name="Revolute_3">
      <command_interface name="position"/>
      <state_interface name="position"/>
      <state_interface name="velocity"/>
      <initial_position>-1.57</initial_position>
    </joint>
    <joint name="Revolute_4">
      <command_interface name="position"/>
      <state_interface name="position"/>
      <state_interface name="velocity"/>
      <initial_position>0.0</initial_position>
    </joint>
    <joint name="Revolute_5">
      <command_interface name="position"/>
      <state_interface name="position"/>
      <state_interface name="velocity"/>
      <initial_position>0.0</initial_position>
    </joint>
    <joint name="Revolute_6">
      <command_interface name="position"/>
      <state_interface name="position"/>
      <state_interface name="velocity"/>
      <initial_position>0.0</initial_position>
    </joint>
  </ros2_control>
</robot>
